<?xml version="1.0"?>
<robot xmlns:xacro="http://www.ros.org/wiki/xacro">

    <!-- Define the shape of the robot's two wheels in meters -->
    <xacro:property name="wheel_radius" value="0.0675"/>
    <xacro:property name="wheel_width" value="0.04"/>
    <xacro:property name="wheel_mass" value="1"/>

    <xacro:macro name="traction_wheel" params="prefix pos_X pos_Y pos_Z pos_r pos_p pos_y">
        <joint name="joint_${prefix}" type="continuous">
            <parent link="base_link" />
            <child link="${prefix}" />
            <origin rpy="${pos_r} ${pos_p} ${pos_y}" xyz="${pos_X} ${pos_Y} ${pos_Z}" />
            <axis xyz="1 0 0" />
        </joint>

        <gazebo reference="${prefix}">
            <selfCollide>false</selfCollide>
            <mu1>1.5</mu1>
            <mu2>1.5</mu2>
            <kp>1000000.0</kp>
            <kd>100.0</kd>
        </gazebo>

        <link name="${prefix}">
            <inertial>
                <mass value="${wheel_mass}" />
                <origin rpy="0 1.57 0" xyz="0 0 0" />
                <inertia ixx="${(2/5) * wheel_mass * (wheel_radius * wheel_radius)}" ixy="0" ixz="0"
                         iyy="${(2/5) * wheel_mass * (wheel_radius * wheel_radius)}" iyz="0"
                         izz="${(2/5) * wheel_mass * (wheel_radius * wheel_radius)}" />
            </inertial>
            <collision name="${prefix}_collision">
                <origin rpy="0 1.57 0" xyz="0 0 0" />
                <geometry>
                    <cylinder length="${wheel_width}" radius="${wheel_radius}"/>
                </geometry>
            </collision>
            <visual name="${prefix}_visual">
                <origin rpy="0 0 0" xyz="0 0 0" />
                <geometry>
                    <mesh filename="file:///$(find ugv_robots_descriptions)/robots_description/l1br/meshes/wheel.dae" scale="1 1 1" />
                </geometry>
            </visual>
        </link>
    </xacro:macro>

    <xacro:traction_wheel prefix="left_wheel" pos_X="0" pos_Y="0.296395" pos_Z="-0.0118" pos_r="0" pos_p="0" pos_y="1.57" />
    <xacro:traction_wheel prefix="right_wheel" pos_X="0" pos_Y="-0.296395" pos_Z="-0.0118" pos_r="0" pos_p="0" pos_y="1.57" />
</robot>