<?xml version="1.0"?>
<robot xmlns:xacro="http://www.ros.org/wiki/xacro">

    <!-- Define the shape of the robot's tray in meters -->
    <xacro:property name="tray_radius" value="0.2"/>
    <!-- antigo raio era 0.2 -->
    <xacro:property name="tray_width" value="0.03"/>

    <xacro:macro name="tray">
        <link name="tray">
        <visual name="tray_visual">
            <origin xyz="0 0 0.0118" rpy="0 0 0"/>
            <geometry>
                <mesh filename="file:///$(find ugv_robots_descriptions)/robots_description/l1br/meshes/tray.dae" scale="1 1 1"/>
            </geometry>
        </visual>
        
        <collision name="tray_collision">
            <origin xyz="0 0 0.105" rpy="0 0 0"/>
            <geometry>
            <cylinder length="${tray_width}" radius="${tray_radius}"/>
            </geometry>
        </collision>
        
        <inertial>
            <mass value="0.5" />
            <origin rpy="0 0 0" xyz="0 0 0" />
            <inertia ixx="${(2/5) * 0.5 * (tray_radius * tray_radius)}" ixy="0.0" ixz="0.0"
                    iyy="${(2/5) * 0.5 * (tray_radius * tray_radius)}" iyz="0.0"
                    izz="${(2/5) * 0.5 * (tray_radius * tray_radius)}" />
        </inertial>
        </link>

        <gazebo reference="tray">
            <selfCollide>true</selfCollide>
            <mu1 value="2" />
            <mu2 value="2" />
            <kp value="10000000.0" />
            <kd value="10000" />
            <fdir1 value="0 0 0" />
        </gazebo>

        <!-- <joint name="joint_prismatic_tray" type="prismatic"> -->
                <!-- <parent link="base_link" /> -->
                <!-- <child link="tray" /> -->
                <!-- <origin rpy="0 0 0" xyz="0 0.015047 0" /> -->
                <!-- <axis xyz="0 0 1"/> -->
                <!-- <limit effort="1000.0" lower="0" upper="0.3" velocity="0.5"/> -->
        <!-- </joint> -->

        <joint name="joint_tray" type="revolute">
                <parent link="piston_base" />
                <child link="tray" />
                <origin rpy="0 0 0" xyz="0 0 -0.08" />
                <axis xyz="0 0 1"/>
                <limit effort="100" lower="-6" upper="6" velocity="0.1"/>
        </joint>
    </xacro:macro>
</robot>